2019-08-20 14:43:26,005 | ERROR | __init__.py | __init__ | 86 | alchemy_error_handler | (pymysql.err.OperationalError) (2013, 'Lost connection to MySQL server during query ([Errno 104] Connection reset by peer)')
[SQL: SELECT tb_users.password AS tb_users_password, tb_users.id AS tb_users_id, tb_users.username AS tb_users_username, tb_users.enabled AS tb_users_enabled, tb_users.deleted AS tb_users_deleted, tb_users.`registrationTime` AS `tb_users_registrationTime`, tb_users.`registrationHost` AS `tb_users_registrationHost`, tb_users.phone AS tb_users_phone, tb_users.email AS tb_users_email, tb_users.google AS tb_users_google, tb_users.`verificationByGoogle` AS `tb_users_verificationByGoogle`, tb_users.`verificationByPhone` AS `tb_users_verificationByPhone`, tb_users.`verificationByEmail` AS `tb_users_verificationByEmail`, tb_users.`accumulatedSystemDeposit` AS `tb_users_accumulatedSystemDeposit`, tb_users.`systemDepositLimitOnce` AS `tb_users_systemDepositLimitOnce`, tb_users.`systemDepositLimitTotal` AS `tb_users_systemDepositLimitTotal`, tb_users.`systemDepositLimitCount` AS `tb_users_systemDepositLimitCount`, tb_users.`lastLoginTime` AS `tb_users_lastLoginTime`, tb_users.`lastLoginIP` AS `tb_users_lastLoginIP`, tb_users.`withdrawallimitOnce` AS `tb_users_withdrawallimitOnce`, tb_users.`withdrawallimitSumCeiling` AS `tb_users_withdrawallimitSumCeiling`, tb_users.`withdrawallimitSum` AS `tb_users_withdrawallimitSum`, tb_users.chat AS tb_users_chat, tb_users.remark AS tb_users_remark, tb_users.nickname AS tb_users_nickname, tb_users.head AS tb_users_head 
FROM tb_users 
WHERE tb_users.username = %(username_1)s AND tb_users.deleted != %(deleted_1)s 
 LIMIT %(param_1)s]
[parameters: {'deleted_1': 1, 'username_1': 'default', 'param_1': 1}]
(Background on this error at: http://sqlalche.me/e/e3q8)
Traceback (most recent call last):
  File "/home/yc/feature_As/venv/lib/python3.5/site-packages/pymysql/connections.py", line 691, in _read_bytes
    data = self._rfile.read(num_bytes)
  File "/usr/lib/python3.5/socket.py", line 575, in readinto
    return self._sock.recv_into(b)
ConnectionResetError: [Errno 104] Connection reset by peer

During handling of the above exception, another exception occurred:

Traceback (most recent call last):
  File "/home/yc/feature_As/venv/lib/python3.5/site-packages/sqlalchemy/engine/base.py", line 1244, in _execute_context
    cursor, statement, parameters, context
  File "/home/yc/feature_As/venv/lib/python3.5/site-packages/sqlalchemy/engine/default.py", line 552, in do_execute
    cursor.execute(statement, parameters)
  File "/home/yc/feature_As/venv/lib/python3.5/site-packages/pymysql/cursors.py", line 170, in execute
    result = self._query(query)
  File "/home/yc/feature_As/venv/lib/python3.5/site-packages/pymysql/cursors.py", line 328, in _query
    conn.query(q)
  File "/home/yc/feature_As/venv/lib/python3.5/site-packages/pymysql/connections.py", line 517, in query
    self._affected_rows = self._read_query_result(unbuffered=unbuffered)
  File "/home/yc/feature_As/venv/lib/python3.5/site-packages/pymysql/connections.py", line 732, in _read_query_result
    result.read()
  File "/home/yc/feature_As/venv/lib/python3.5/site-packages/pymysql/connections.py", line 1075, in read
    first_packet = self.connection._read_packet()
  File "/home/yc/feature_As/venv/lib/python3.5/site-packages/pymysql/connections.py", line 657, in _read_packet
    packet_header = self._read_bytes(4)
  File "/home/yc/feature_As/venv/lib/python3.5/site-packages/pymysql/connections.py", line 699, in _read_bytes
    "Lost connection to MySQL server during query (%s)" % (e,))
pymysql.err.OperationalError: (2013, 'Lost connection to MySQL server during query ([Errno 104] Connection reset by peer)')

The above exception was the direct cause of the following exception:

Traceback (most recent call last):
  File "/home/yc/feature_As/venv/lib/python3.5/site-packages/flask/app.py", line 1813, in full_dispatch_request
    rv = self.dispatch_request()
  File "/home/yc/feature_As/venv/lib/python3.5/site-packages/flask/app.py", line 1799, in dispatch_request
    return self.view_functions[rule.endpoint](**req.view_args)
  File "/home/yc/feature_As/venv/lib/python3.5/site-packages/flask/views.py", line 88, in view
    return self.dispatch_request(*args, **kwargs)
  File "/home/yc/feature_As/venv/lib/python3.5/site-packages/flask/views.py", line 158, in dispatch_request
    return meth(*args, **kwargs)
  File "/home/yc/feature_As/app/auth/views.py", line 24, in post
    user = User.query.filter(User.username == username, User.deleted != 1).first()
  File "/home/yc/feature_As/venv/lib/python3.5/site-packages/sqlalchemy/orm/query.py", line 3215, in first
    ret = list(self[0:1])
  File "/home/yc/feature_As/venv/lib/python3.5/site-packages/sqlalchemy/orm/query.py", line 3007, in __getitem__
    return list(res)
  File "/home/yc/feature_As/venv/lib/python3.5/site-packages/sqlalchemy/orm/query.py", line 3317, in __iter__
    return self._execute_and_instances(context)
  File "/home/yc/feature_As/venv/lib/python3.5/site-packages/sqlalchemy/orm/query.py", line 3342, in _execute_and_instances
    result = conn.execute(querycontext.statement, self._params)
  File "/home/yc/feature_As/venv/lib/python3.5/site-packages/sqlalchemy/engine/base.py", line 988, in execute
    return meth(self, multiparams, params)
  File "/home/yc/feature_As/venv/lib/python3.5/site-packages/sqlalchemy/sql/elements.py", line 287, in _execute_on_connection
    return connection._execute_clauseelement(self, multiparams, params)
  File "/home/yc/feature_As/venv/lib/python3.5/site-packages/sqlalchemy/engine/base.py", line 1107, in _execute_clauseelement
    distilled_params,
  File "/home/yc/feature_As/venv/lib/python3.5/site-packages/sqlalchemy/engine/base.py", line 1248, in _execute_context
    e, statement, parameters, cursor, context
  File "/home/yc/feature_As/venv/lib/python3.5/site-packages/sqlalchemy/engine/base.py", line 1466, in _handle_dbapi_exception
    util.raise_from_cause(sqlalchemy_exception, exc_info)
  File "/home/yc/feature_As/venv/lib/python3.5/site-packages/sqlalchemy/util/compat.py", line 383, in raise_from_cause
    reraise(type(exception), exception, tb=exc_tb, cause=cause)
  File "/home/yc/feature_As/venv/lib/python3.5/site-packages/sqlalchemy/util/compat.py", line 128, in reraise
    raise value.with_traceback(tb)
  File "/home/yc/feature_As/venv/lib/python3.5/site-packages/sqlalchemy/engine/base.py", line 1244, in _execute_context
    cursor, statement, parameters, context
  File "/home/yc/feature_As/venv/lib/python3.5/site-packages/sqlalchemy/engine/default.py", line 552, in do_execute
    cursor.execute(statement, parameters)
  File "/home/yc/feature_As/venv/lib/python3.5/site-packages/pymysql/cursors.py", line 170, in execute
    result = self._query(query)
  File "/home/yc/feature_As/venv/lib/python3.5/site-packages/pymysql/cursors.py", line 328, in _query
    conn.query(q)
  File "/home/yc/feature_As/venv/lib/python3.5/site-packages/pymysql/connections.py", line 517, in query
    self._affected_rows = self._read_query_result(unbuffered=unbuffered)
  File "/home/yc/feature_As/venv/lib/python3.5/site-packages/pymysql/connections.py", line 732, in _read_query_result
    result.read()
  File "/home/yc/feature_As/venv/lib/python3.5/site-packages/pymysql/connections.py", line 1075, in read
    first_packet = self.connection._read_packet()
  File "/home/yc/feature_As/venv/lib/python3.5/site-packages/pymysql/connections.py", line 657, in _read_packet
    packet_header = self._read_bytes(4)
  File "/home/yc/feature_As/venv/lib/python3.5/site-packages/pymysql/connections.py", line 699, in _read_bytes
    "Lost connection to MySQL server during query (%s)" % (e,))
sqlalchemy.exc.OperationalError: (pymysql.err.OperationalError) (2013, 'Lost connection to MySQL server during query ([Errno 104] Connection reset by peer)')
[SQL: SELECT tb_users.password AS tb_users_password, tb_users.id AS tb_users_id, tb_users.username AS tb_users_username, tb_users.enabled AS tb_users_enabled, tb_users.deleted AS tb_users_deleted, tb_users.`registrationTime` AS `tb_users_registrationTime`, tb_users.`registrationHost` AS `tb_users_registrationHost`, tb_users.phone AS tb_users_phone, tb_users.email AS tb_users_email, tb_users.google AS tb_users_google, tb_users.`verificationByGoogle` AS `tb_users_verificationByGoogle`, tb_users.`verificationByPhone` AS `tb_users_verificationByPhone`, tb_users.`verificationByEmail` AS `tb_users_verificationByEmail`, tb_users.`accumulatedSystemDeposit` AS `tb_users_accumulatedSystemDeposit`, tb_users.`systemDepositLimitOnce` AS `tb_users_systemDepositLimitOnce`, tb_users.`systemDepositLimitTotal` AS `tb_users_systemDepositLimitTotal`, tb_users.`systemDepositLimitCount` AS `tb_users_systemDepositLimitCount`, tb_users.`lastLoginTime` AS `tb_users_lastLoginTime`, tb_users.`lastLoginIP` AS `tb_users_lastLoginIP`, tb_users.`withdrawallimitOnce` AS `tb_users_withdrawallimitOnce`, tb_users.`withdrawallimitSumCeiling` AS `tb_users_withdrawallimitSumCeiling`, tb_users.`withdrawallimitSum` AS `tb_users_withdrawallimitSum`, tb_users.chat AS tb_users_chat, tb_users.remark AS tb_users_remark, tb_users.nickname AS tb_users_nickname, tb_users.head AS tb_users_head 
FROM tb_users 
WHERE tb_users.username = %(username_1)s AND tb_users.deleted != %(deleted_1)s 
 LIMIT %(param_1)s]
[parameters: {'deleted_1': 1, 'username_1': 'default', 'param_1': 1}]
(Background on this error at: http://sqlalche.me/e/e3q8)
2019-08-20 18:19:10,032 | INFO | transactionDetails.py | transactionDetails | 148 | job_1 | 同步交易记录 2019-08-20 18:04:11至 2019-08-20 18:19:10 开始
